<?xml version="1.0" encoding="utf-8"?>

<robot name="robot_model_core">
  
  <!-- Base Link -->
  <link name="base_link">
    <inertial>
      <origin xyz="-9.7145E-17 -5.5511E-17 -0.019853" rpy="0 0 0" />
      <mass value="1.2174" />
      <inertia
        ixx="0.013551"
        ixy="1.0803E-17"
        ixz="-6.541E-19"
        iyy="0.013822"
        iyz="2.5594E-19"
        izz="0.026879" />
    </inertial>

    <visual>
      <origin xyz="0 0 0" rpy="0 0 0" />
      <geometry>
        <mesh filename="package://robot_model/meshes/base_link.STL" />
      </geometry>
      <material name="">
        <color rgba="0.75294 0.75294 0.75294 1" />
      </material>
    </visual>

    <collision>
      <origin xyz="0 0 0" rpy="0 0 0" />
      <geometry>
        <mesh filename="package://robot_model/meshes/base_link.STL" />
      </geometry>
    </collision>
  </link>
  
  
  <!-- Left Wheel Link -->
  <link name="left_wheel_link">
    <inertial>
      <origin xyz="6.1062E-16 0.013537 0" rpy="0 0 0" />
      <mass value="0.3144" />
      <inertia
        ixx="0.00033834"
        ixy="7.173E-19"
        ixz="3.8968E-19"
        iyy="0.0006227"
        iyz="2.0602E-20"
        izz="0.00033834" />
    </inertial>

    <visual>
      <origin xyz="0 -0.0127 0" rpy="0 0 0" />
      <geometry>
        <mesh filename="package://robot_model/meshes/left_wheel_link.STL" />
      </geometry>
      <material name="">
        <color rgba="0.79216 0.81961 0.93333 1" />
      </material>
    </visual>

    <collision>
      <origin xyz="0 -0.0127 0" rpy="0 0 0" />
      <geometry>
        <mesh filename="package://robot_model/meshes/left_wheel_link.STL" />
      </geometry>
    </collision>
  </link>
  
  <!-- Left Wheel Joint -->
  <joint name="left_wheel_joint" type="continuous">
    <origin xyz="0 -0.1527 -0.035" rpy="0 0 0" />
    <parent link="base_link" />
    <child link="left_wheel_link" />
    <axis xyz="0 -1 0" />
    <limit effort="1" velocity="1" />
  </joint>
  
  
  <!-- Right Wheel Link -->
  <link name="right_wheel_link">
    <inertial>
      <origin xyz="1.6653E-16 -0.013537 -2.7756E-17" rpy="0 0 0" />
      <mass value="0.3144" />
      <inertia
        ixx="0.00033834"
        ixy="-1.4697E-18"
        ixz="-1.8425E-19"
        iyy="0.0006227"
        iyz="-3.955E-21"
        izz="0.00033834" />
    </inertial>

    <visual>
      <origin xyz="0 0.0127 0" rpy="0 0 0" />
      <geometry>
        <mesh filename="package://robot_model/meshes/right_wheel_link.STL" />
      </geometry>
      <material name="">
        <color rgba="0.79216 0.81961 0.93333 1" />
      </material>
    </visual>

    <collision>
      <origin xyz="0 0.0127 0" rpy="0 0 0" />
      <geometry>
        <mesh filename="package://robot_model/meshes/right_wheel_link.STL" />
      </geometry>
    </collision>
  </link>
  
  <!-- Right Wheel Joint -->
  <joint name="right_wheel_joint" type="continuous">
    <origin xyz="0 0.1527 -0.035" rpy="0 0 0" />
    <parent link="base_link" />
    <child link="right_wheel_link" />
    <axis xyz="0 -1 0" />
    <limit effort="1" velocity="1" />
  </joint>


  <!-- Front Left Caster Link -->
  <link name="fl_caster_link">
    <inertial>
      <origin xyz="2.7756E-17 0.0125 0" rpy="0 0 0" />
      <mass value="0.047169" />
      <inertia
        ixx="9.3192E-06"
        ixy="5.9932E-21"
        ixz="2.812E-41"
        iyy="1.3638E-05"
        iyz="1.1918E-38"
        izz="9.3192E-06" />
    </inertial>

    <visual>
      <origin xyz="0 -0.0125 0" rpy="0 0 0" />
      <geometry>
        <mesh filename="package://robot_model/meshes/fl_caster_link.STL" />
      </geometry>
      <material name="">
        <color rgba="0.79216 0.81961 0.93333 1" />
      </material>
    </visual>

    <collision>
      <origin xyz="0 -0.0125 0" rpy="0 0 0" />
      <geometry>
        <mesh filename="package://robot_model/meshes/fl_caster_link.STL" />
      </geometry>
    </collision>
  </link>
  
  <!-- Front Left Caster Joint -->
  <joint name="fl_caster_joint" type="continuous">
    <origin xyz="0.095 -0.09 -0.0735" rpy="0 0 0" />
    <parent link="base_link" />
    <child link="fl_caster_link" />
    <axis xyz="0 -1 0" />
    <limit effort="1" velocity="1" />
  </joint>


  <!-- Front Right Caster Link -->
  <link name="fr_caster_link">
    <inertial>
      <origin xyz="2.7756E-17 0.0125 0" rpy="0 0 0" />
      <mass value="0.047169" />
      <inertia
        ixx="9.3192E-06"
        ixy="5.9888E-21"
        ixz="2.812E-41"
        iyy="1.3638E-05"
        iyz="1.1918E-38"
        izz="9.3192E-06" />
    </inertial>

    <visual>
      <origin xyz="0 0.0125 0" rpy="0 0 0" />
      <geometry>
        <mesh filename="package://robot_model/meshes/fr_caster_link.STL" />
      </geometry>
      <material name="">
        <color rgba="0.79216 0.81961 0.93333 1" />
      </material>
    </visual>

    <collision>
      <origin xyz="0 0.0125 0" rpy="0 0 0" />
      <geometry>
        <mesh filename="package://robot_model/meshes/fr_caster_link.STL" />
      </geometry>
    </collision>
  </link>
  
  <!-- Front Right Caster Link -->
  <joint name="fr_caster_joint" type="continuous">
    <origin xyz="0.095 0.09 -0.0735" rpy="0 0 0" />
    <parent link="base_link" />
    <child link="fr_caster_link" />
    <axis xyz="0 -1 0" />
    <limit effort="1" velocity="1" />
  </joint>
  
  
  <!-- Rear Left Caster Link -->
  <link name="rl_caster_link">
    <inertial>
      <origin xyz="1.648E-17 0.0125 0" rpy="0 0 0" />
      <mass value="0.047169" />
      <inertia
        ixx="9.3192E-06"
        ixy="5.9888E-21"
        ixz="2.812E-41"
        iyy="1.3638E-05"
        iyz="1.1918E-38"
        izz="9.3192E-06" />
    </inertial>

    <visual>
      <origin xyz="0 -0.0125 0" rpy="0 0 0" />
      <geometry>
        <mesh filename="package://robot_model/meshes/rl_caster_link.STL" />
      </geometry>
      <material name="">
        <color rgba="0.79216 0.81961 0.93333 1" />
      </material>
    </visual>

    <collision>
      <origin xyz="0 -0.0125 0" rpy="0 0 0" />
      <geometry>
        <mesh filename="package://robot_model/meshes/rl_caster_link.STL" />
      </geometry>
    </collision>
  </link>
  
  <!-- Rear Left Caster Joint -->
  <joint name="rl_caster_joint" type="continuous">
    <origin xyz="-0.095 -0.09 -0.0735" rpy="0 0 0" />
    <parent link="base_link" />
    <child link="rl_caster_link" />
    <axis xyz="0 -1 0" />
    <limit effort="1" velocity="1" />
  </joint>
  
  
  <!-- Rear Right Caster Link -->
  <link name="rr_caster_link">
    <inertial>
      <origin xyz="-1.8215E-17 -0.0125 0" rpy="0 0 0" />
      <mass value="0.047169" />
      <inertia
        ixx="9.3192E-06"
        ixy="5.9932E-21"
        ixz="2.812E-41"
        iyy="1.3638E-05"
        iyz="1.1918E-38"
        izz="9.3192E-06" />
    </inertial>

    <visual>
      <origin xyz="0 0.0125 0" rpy="0 0 0" />
      <geometry>
        <mesh filename="package://robot_model/meshes/rr_caster_link.STL" />
      </geometry>
      <material name="">
        <color rgba="0.79216 0.81961 0.93333 1" />
      </material>
    </visual>

    <collision>
      <origin xyz="0 0.0125 0" rpy="0 0 0" />
      <geometry>
        <mesh filename="package://robot_model/meshes/rr_caster_link.STL" />
      </geometry>
    </collision>
  </link>
  
  <!-- Rear Right Caster Joint -->
  <joint name="rr_caster_joint" type="continuous">
    <origin xyz="-0.095 0.09 -0.0735" rpy="0 0 0" />
    <parent link="base_link" />
    <child  link="rr_caster_link" />
    <axis xyz="0 -1 0" />
    <limit effort="1" velocity="1" />
  </joint>
  
  
  <!-- Camera Base Link -->
  <link name="cam_base_link">
    <inertial>
      <origin xyz="-2.7756E-17 0 -0.0165" rpy="0 0 0" />
      <mass value="0.0069206" />
      <inertia
        ixx="1.8657E-06"
        ixy="-6.5702E-22"
        ixz="-2.5849E-23"
        iyy="1.3857E-06"
        iyz="-1.4208E-22"
        izz="8.2651E-07" />
    </inertial>

    <visual>
      <origin xyz="0 0 0" rpy="0 0 0" />
      <geometry>
        <mesh filename="package://robot_model/meshes/cam_base_link.STL" />
      </geometry>
      <material name="">
        <color rgba="0.9098 0.44314 0.031373 1" />
      </material>
    </visual>

    <collision>
      <origin xyz="0 0 0" rpy="0 0 0" />
      <geometry>
        <mesh filename="package://robot_model/meshes/cam_base_link.STL" />
      </geometry>
    </collision>
  </link>
  
  <!-- Camera Base Joint -->
  <joint name="cam_base_joint" type="fixed">
    <origin xyz="0.13 0 0.033" rpy="0 0 0" />
    <parent link="base_link" />
    <child link="cam_base_link" />
    <axis xyz="0 0 0" />
  </joint>
</robot>
